
FAIL returning early from an iteration doesn't crash promise_test: Unhandled rejection with value: object "TypeError: navigator.storage.getDirectory is not a function. (In 'navigator.storage.getDirectory()', 'navigator.storage.getDirectory' is undefined)"
FAIL @@asyncIterator: full iteration works promise_test: Unhandled rejection with value: object "TypeError: navigator.storage.getDirectory is not a function. (In 'navigator.storage.getDirectory()', 'navigator.storage.getDirectory' is undefined)"
FAIL entries: full iteration works promise_test: Unhandled rejection with value: object "TypeError: navigator.storage.getDirectory is not a function. (In 'navigator.storage.getDirectory()', 'navigator.storage.getDirectory' is undefined)"
FAIL values: full iteration works promise_test: Unhandled rejection with value: object "TypeError: navigator.storage.getDirectory is not a function. (In 'navigator.storage.getDirectory()', 'navigator.storage.getDirectory' is undefined)"
FAIL keys: full iteration works promise_test: Unhandled rejection with value: object "TypeError: navigator.storage.getDirectory is not a function. (In 'navigator.storage.getDirectory()', 'navigator.storage.getDirectory' is undefined)"
FAIL iteration while iterator gets garbage collected promise_test: Unhandled rejection with value: object "TypeError: navigator.storage.getDirectory is not a function. (In 'navigator.storage.getDirectory()', 'navigator.storage.getDirectory' is undefined)"

