
FAIL SyncAccessHandle.close is idempotent promise_test: Unhandled rejection with value: object "InvalidStateError: The object is in an invalid state."
FAIL SyncAccessHandle.close is idempotent when called immediately promise_test: Unhandled rejection with value: object "UnknownError: The operation failed for an unknown transient reason (e.g. out of memory)."
FAIL SyncAccessHandle.read fails after SyncAccessHandle.close settles assert_throws_dom: function "() => handle.read(readBuffer, {at: 0})" threw object "TypeError: handle.read is not a function. (In 'handle.read(readBuffer, {at: 0})', 'handle.read' is undefined)" that is not a DOMException InvalidStateError: property "code" is equal to undefined, expected 11
FAIL SyncAccessHandle.read fails immediately after calling SyncAccessHandle.close assert_throws_dom: function "() => handle.read(readBuffer, {at: 0})" threw object "TypeError: handle.read is not a function. (In 'handle.read(readBuffer, {at: 0})', 'handle.read' is undefined)" that is not a DOMException InvalidStateError: property "code" is equal to undefined, expected 11
FAIL SyncAccessHandle.write fails after SyncAccessHandle.close settles assert_throws_dom: function "() => handle.write(writeBuffer, {at: 0})" threw object "TypeError: handle.write is not a function. (In 'handle.write(writeBuffer, {at: 0})', 'handle.write' is undefined)" that is not a DOMException InvalidStateError: property "code" is equal to undefined, expected 11
FAIL SyncAccessHandle.write fails immediately after calling SyncAccessHandle.close assert_throws_dom: function "() => handle.write(writeBuffer, {at: 0})" threw object "TypeError: handle.write is not a function. (In 'handle.write(writeBuffer, {at: 0})', 'handle.write' is undefined)" that is not a DOMException InvalidStateError: property "code" is equal to undefined, expected 11
FAIL SyncAccessHandle.flush fails after SyncAccessHandle.close settles promise_rejects_dom: function "function () { throw e }" threw object "UnknownError: The operation failed for an unknown transient reason (e.g. out of memory)." that is not a DOMException InvalidStateError: property "code" is equal to 0, expected 11
FAIL SyncAccessHandle.flush fails immediately after calling SyncAccessHandle.close promise_rejects_dom: function "function () { throw e }" threw object "UnknownError: The operation failed for an unknown transient reason (e.g. out of memory)." that is not a DOMException InvalidStateError: property "code" is equal to 0, expected 11
FAIL SyncAccessHandle.getSize fails after SyncAccessHandle.close settles promise_rejects_dom: function "function () { throw e }" threw object "UnknownError: The operation failed for an unknown transient reason (e.g. out of memory)." that is not a DOMException InvalidStateError: property "code" is equal to 0, expected 11
FAIL SyncAccessHandle.getSize fails immediately after calling SyncAccessHandle.close promise_rejects_dom: function "function () { throw e }" threw object "UnknownError: The operation failed for an unknown transient reason (e.g. out of memory)." that is not a DOMException InvalidStateError: property "code" is equal to 0, expected 11
FAIL SyncAccessHandle.truncate fails after SyncAccessHandle.close settles promise_rejects_dom: function "function () { throw e }" threw object "UnknownError: The operation failed for an unknown transient reason (e.g. out of memory)." that is not a DOMException InvalidStateError: property "code" is equal to 0, expected 11
FAIL SyncAccessHandle.truncate fails immediately after calling SyncAccessHandle.close promise_rejects_dom: function "function () { throw e }" threw object "UnknownError: The operation failed for an unknown transient reason (e.g. out of memory)." that is not a DOMException InvalidStateError: property "code" is equal to 0, expected 11

